Workbook
Name bs_d1: '03_BS_Engine'!$C$6
Name bs_d2: '03_BS_Engine'!$C$7
Name dividend_yield: '02_Market_Data'!$C$11
Name implied_volatlity: '02_Market_Data'!$C$10
Name lot_size: '02_Market_Data'!$C$12
Name n_d1: '03_BS_Engine'!$D$6
Name n_d2: '03_BS_Engine'!$D$7
Name risk_free_rate: '02_Market_Data'!$C$9
Name spot_price: '02_Market_Data'!$C$6
Name strike_price: '02_Market_Data'!$C$7
Name time_to_maturity: '02_Market_Data'!$C$8

Sheet 01_Dashboard
B2: 🏦 BLACK-SCHOLES OPTIONS PRICING · NIFTY 50 | NSE Prop Desk Dashboard
B3: Merton (1973) Extension · All values in ₹ · FAST Standard · Model v2.0 · Lot Size: NIFTY 50 = 50
B5: SECTION A · Live Pricing & Greeks Summary
B6: Metric | C6: CALL | D6: PUT | E6: CALL × Lot (₹) | F6: PUT × Lot (₹)
B7: Premium (₹) | C7: ='03_BS_Engine'!C11 -> 421.30352 | D7: ='03_BS_Engine'!C12 -> 324.83201 | E7: ='03_BS_Engine'!D11 -> 21065.176 | F7: ='03_BS_Engine'!D12 -> 16241.6
B8: Delta | C8: ='04_Risk_Greeks'!C5 -> 0.54904817 | D8: ='04_Risk_Greeks'!C6 -> -0.44975255 | E8: ='04_Risk_Greeks'!D5 -> 27.452409 | F8: ='04_Risk_Greeks'!D6 -> -22.487627
B9: Gamma | C9: ='04_Risk_Greeks'!C7 -> 0.00042358569 | D9: ='04_Risk_Greeks'!C7 -> 0.00042358569 | E9: ='04_Risk_Greeks'!D7 -> 0.021179284 | F9: ='04_Risk_Greeks'!D7 -> 0.021179284
B10: Vega (per 1% vol) | C10: ='04_Risk_Greeks'!C8 -> 24.601857 | D10: ='04_Risk_Greeks'!C8 -> 24.601857 | E10: ='04_Risk_Greeks'!D8 -> 1230.0928 | F10: ='04_Risk_Greeks'!D8 -> 1230.0928
B11: Theta (Daily, ₹) | C11: ='04_Risk_Greeks'!C9 -> -8.0583044 | D11: ='04_Risk_Greeks'!C10 -> -4.765713 | E11: ='04_Risk_Greeks'!D9 -> -402.91522 | F11: ='04_Risk_Greeks'!D10 -> -238.28565
B14: SECTION B · Key Inputs Snapshot (linked from Market Data)
B15: Spot | C15: Strike | D15: Expiry (T) | E15: Rate (r) | F15: IV (σ)
B16: ='02_Market_Data'!C6 -> 22000 | C16: ='02_Market_Data'!C7 -> 22000 | D16: ='02_Market_Data'!C8 -> 0.08 | E16: ='02_Market_Data'!C9 -> 0.07 | F16: ='02_Market_Data'!C10 -> 0.15
B19: SECTION C · P&L Payoff Matrix at Expiration (NIFTY ±10% Range)
B20: Sim Spot (₹) | C20: Call P&L (₹) | D20: Put P&L (₹) | E20: Move (%) | F20: Net Straddle (₹) | H20: Helper column
B21: =$B$16*(1+(E21)) -> 19800 | C21: =MAX(B21-$C$16,0)*lot_size-$C$7*lot_size -> -21065.176 | D21: =MAX($C$16-B21,0)*lot_size-$D$7*lot_size -> 93758.4 | E21: =-0.1 -> -0.1 | F21: =C21+D21 -> 72693.223 | H21: 0
B22: =$B$16*(1+(E22)) -> 20020 | C22: =MAX(B22-$C$16,0)*lot_size-$C$7*lot_size -> -21065.176 | D22: =MAX($C$16-B22,0)*lot_size-$D$7*lot_size -> 82758.4 | E22: =-0.09 -> -0.09 | F22: =C22+D22 -> 61693.223 | H22: 0
B23: =$B$16*(1+(E23)) -> 20240 | C23: =MAX(B23-$C$16,0)*lot_size-$C$7*lot_size -> -21065.176 | D23: =MAX($C$16-B23,0)*lot_size-$D$7*lot_size -> 71758.4 | E23: =-0.08 -> -0.08 | F23: =C23+D23 -> 50693.223 | H23: 0
B24: =$B$16*(1+(E24)) -> 20460 | C24: =MAX(B24-$C$16,0)*lot_size-$C$7*lot_size -> -21065.176 | D24: =MAX($C$16-B24,0)*lot_size-$D$7*lot_size -> 60758.4 | E24: =-0.07 -> -0.07 | F24: =C24+D24 -> 39693.223 | H24: 0
B25: =$B$16*(1+(E25)) -> 20680 | C25: =MAX(B25-$C$16,0)*lot_size-$C$7*lot_size -> -21065.176 | D25: =MAX($C$16-B25,0)*lot_size-$D$7*lot_size -> 49758.4 | E25: =-0.06 -> -0.06 | F25: =C25+D25 -> 28693.223 | H25: 0
B26: =$B$16*(1+(E26)) -> 20900 | C26: =MAX(B26-$C$16,0)*lot_size-$C$7*lot_size -> -21065.176 | D26: =MAX($C$16-B26,0)*lot_size-$D$7*lot_size -> 38758.4 | E26: =-0.05 -> -0.05 | F26: =C26+D26 -> 17693.223 | H26: 0
B27: =$B$16*(1+(E27)) -> 21120 | C27: =MAX(B27-$C$16,0)*lot_size-$C$7*lot_size -> -21065.176 | D27: =MAX($C$16-B27,0)*lot_size-$D$7*lot_size -> 27758.4 | E27: =-0.04 -> -0.04 | F27: =C27+D27 -> 6693.2234 | H27: 0
B28: =$B$16*(1+(E28)) -> 21340 | C28: =MAX(B28-$C$16,0)*lot_size-$C$7*lot_size -> -21065.176 | D28: =MAX($C$16-B28,0)*lot_size-$D$7*lot_size -> 16758.4 | E28: =-0.03 -> -0.03 | F28: =C28+D28 -> -4306.7766 | H28: 0
B29: =$B$16*(1+(E29)) -> 21560 | C29: =MAX(B29-$C$16,0)*lot_size-$C$7*lot_size -> -21065.176 | D29: =MAX($C$16-B29,0)*lot_size-$D$7*lot_size -> 5758.3996 | E29: =-0.02 -> -0.02 | F29: =C29+D29 -> -15306.777 | H29: 0
B30: =$B$16*(1+(E30)) -> 21780 | C30: =MAX(B30-$C$16,0)*lot_size-$C$7*lot_size -> -21065.176 | D30: =MAX($C$16-B30,0)*lot_size-$D$7*lot_size -> -5241.6004 | E30: =-0.01 -> -0.01 | F30: =C30+D30 -> -26306.777 | H30: 0
B31: =$B$16*(1+(E31)) -> 22000 | C31: =MAX(B31-$C$16,0)*lot_size-$C$7*lot_size -> -21065.176 | D31: =MAX($C$16-B31,0)*lot_size-$D$7*lot_size -> -16241.6 | E31: =0 -> 0 | F31: =C31+D31 -> -37306.777 | H31: 0
B32: =$B$16*(1+(E32)) -> 22220 | C32: =MAX(B32-$C$16,0)*lot_size-$C$7*lot_size -> -10065.176 | D32: =MAX($C$16-B32,0)*lot_size-$D$7*lot_size -> -16241.6 | E32: =0.01 -> 0.01 | F32: =C32+D32 -> -26306.777 | H32: 0
B33: =$B$16*(1+(E33)) -> 22440 | C33: =MAX(B33-$C$16,0)*lot_size-$C$7*lot_size -> 934.82377 | D33: =MAX($C$16-B33,0)*lot_size-$D$7*lot_size -> -16241.6 | E33: =0.02 -> 0.02 | F33: =C33+D33 -> -15306.777 | H33: 0
B34: =$B$16*(1+(E34)) -> 22660 | C34: =MAX(B34-$C$16,0)*lot_size-$C$7*lot_size -> 11934.824 | D34: =MAX($C$16-B34,0)*lot_size-$D$7*lot_size -> -16241.6 | E34: =0.03 -> 0.03 | F34: =C34+D34 -> -4306.7766 | H34: 0
B35: =$B$16*(1+(E35)) -> 22880 | C35: =MAX(B35-$C$16,0)*lot_size-$C$7*lot_size -> 22934.824 | D35: =MAX($C$16-B35,0)*lot_size-$D$7*lot_size -> -16241.6 | E35: =0.04 -> 0.04 | F35: =C35+D35 -> 6693.2234 | H35: 0
B36: =$B$16*(1+(E36)) -> 23100 | C36: =MAX(B36-$C$16,0)*lot_size-$C$7*lot_size -> 33934.824 | D36: =MAX($C$16-B36,0)*lot_size-$D$7*lot_size -> -16241.6 | E36: =0.05 -> 0.05 | F36: =C36+D36 -> 17693.223 | H36: 0
B37: =$B$16*(1+(E37)) -> 23320 | C37: =MAX(B37-$C$16,0)*lot_size-$C$7*lot_size -> 44934.824 | D37: =MAX($C$16-B37,0)*lot_size-$D$7*lot_size -> -16241.6 | E37: =0.06 -> 0.06 | F37: =C37+D37 -> 28693.223 | H37: 0
B38: =$B$16*(1+(E38)) -> 23540 | C38: =MAX(B38-$C$16,0)*lot_size-$C$7*lot_size -> 55934.824 | D38: =MAX($C$16-B38,0)*lot_size-$D$7*lot_size -> -16241.6 | E38: =0.07 -> 0.07 | F38: =C38+D38 -> 39693.223 | H38: 0
B39: =$B$16*(1+(E39)) -> 23760 | C39: =MAX(B39-$C$16,0)*lot_size-$C$7*lot_size -> 66934.824 | D39: =MAX($C$16-B39,0)*lot_size-$D$7*lot_size -> -16241.6 | E39: =0.08 -> 0.08 | F39: =C39+D39 -> 50693.223 | H39: 0
B40: =$B$16*(1+(E40)) -> 23980 | C40: =MAX(B40-$C$16,0)*lot_size-$C$7*lot_size -> 77934.824 | D40: =MAX($C$16-B40,0)*lot_size-$D$7*lot_size -> -16241.6 | E40: =0.09 -> 0.09 | F40: =C40+D40 -> 61693.223 | H40: 0
B41: =$B$16*(1+(E41)) -> 24200 | C41: =MAX(B41-$C$16,0)*lot_size-$C$7*lot_size -> 88934.824 | D41: =MAX($C$16-B41,0)*lot_size-$D$7*lot_size -> -16241.6 | E41: =0.1 -> 0.1 | F41: =C41+D41 -> 72693.223 | H41: 0

Sheet 02_Market_Data
B2: ⚙ NIFTY 50 Option Pricing — Input Control Panel
B3: Source: NSE/BSE | Blue = user inputs | FAST Model Standard
B5: Parameter | C5: Value | D5: Description / Source
B6: Spot Price (S) | C6: ='05_Sensitivity_Matrix'!O9 -> 22000 | D6: NSE NIFTY 50 Index Level | Source: NSE Live
B7: Strike Price (X) | C7: 22000 | D7: ATM Strike | NSE F&O Contract
B8: Time to Maturity (T, yrs) | C8: ='05_Sensitivity_Matrix'!O10 -> 0.08 | D8: ~29 trading days (1 month expiry)
B9: Risk-Free Rate (r) | C9: 0.07 | D9: 10-Yr G-Sec Yield | Source: RBI
B10: Implied Volatility (σ) | C10: ='05_Sensitivity_Matrix'!O8 -> 0.15 | D10: India VIX proxy | Source: NSE VIX
B11: Dividend Yield (q) | C11: 0.015 | D11: NIFTY 50 Div Yield | Source: NSE
B12: Lot Size | C12: 50 | D12: NIFTY 50 Standard Lot | Source: NSE F&O

Sheet 03_BS_Engine
B2: 📐 Black-Scholes-Merton Pricing Engine | With Merton (1973) Dividend Extension
B4: SECTION A · Intermediate d₁ and d₂ Calculations
B5: Component | C5: Value | D5: Probability
B6: d₁ — Log-Moneyness Adjusted | C6: =(LN(spot_price/strike_price)+(risk_free_rate-dividend_yield+(implied_volatlity^2)/2)*time_to_maturity)/(implied_volatlity*SQRT(time_to_maturity)) -> 0.1249222 | D6: =_xlfn.NORM.S.DIST(bs_d1,TRUE) -> 0.54970743 | F6: 0.54970743
B7: d₂ — Risk-Adjusted Probability | C7: =C6-(implied_volatlity*SQRT(time_to_maturity)) -> 0.082495791 | D7: =_xlfn.NORM.S.DIST(bs_d2,TRUE) -> 0.53287377 | F7: 0.53287377
B9: SECTION B · Option Premiums (Per Share & Per Lot)
B10: Metric | C10: Per Share (₹) | D10: Per Lot (₹) [×Lot Size]
B11: 📞 CALL Premium | C11: =spot_price * EXP(-dividend_yield * time_to_maturity) *n_d1 - strike_price * EXP(-risk_free_rate * time_to_maturity) *n_d2 -> 421.30352 | D11: =C11*lot_size -> 21065.176 | F11: Model market mein thoda sa upside expectation dekh raha hai, isi liye Call option ki value Put option se zyada aa rahi hai.
B12: 📉 PUT Premium | C12: =strike_price*EXP(-risk_free_rate*time_to_maturity)*(1-n_d2) -spot_price*EXP(-dividend_yield*time_to_maturity)*(1-n_d1) -> 324.83201 | D12: =C12*lot_size -> 16241.6
B14: SECTION C · Put-Call Parity Verification
B15: Check | C15: Value (₹) | D15: Notes
B16: LHS: Call − Put | C16: =C11-C12 -> 96.471517 | D16: C11−C12
B17: RHS: S·e^(−qT) − X·e^(−rT) | C17: =spot_price * EXP(-dividend_yield * time_to_maturity) - strike_price * EXP(-risk_free_rate * time_to_maturity) -> 96.471517 | D17: Forward minus PV(K)
B18: PCP Δ (should be ≈ 0) | C18: =C16-C17 -> 0 | D18: Error < 0.01 ₹ = valid ✓

Sheet 04_Risk_Greeks
B2: 🛡 Risk Analytics — Greeks Dashboard | NSE F&O Derivatives
B4: Greek / Metric | C4: Per Share | D4: Position (×LotSize) | F4: PnL Attribution - Call | J4: PnL Attribution - Put
B5: △ Call Delta | C5: =EXP(-dividend_yield * time_to_maturity) * n_d1 -> 0.54904817 | D5: =C5*lot_size -> 27.452409 | F5: Greek / Metric | G5: PnL Contribution | H5: % of Total | J5: Greek / Metric | K5: PnL Contribution | L5: % of Total
B6: △ Put Delta | C6: =-EXP(-dividend_yield * time_to_maturity) * _xlfn.NORM.S.DIST(-bs_d1, TRUE) -> -0.44975255 | D6: =C6*lot_size -> -22.487627 | F6: △ Call Delta | G6: =D5 * $C$15 -> 2745.2409 | H6: =G6/$G$10 -> 0.55929357 | J6: △ Put Delta | K6: =D6 * $C$15 -> -2248.7627 | L6: =ABS(K6)/(ABS($K$6)+ABS($K$7)+ABS($K$8)+ABS($K$9)) -> 0.44502368
B7: Γ Gamma | C7: =(EXP(-dividend_yield * time_to_maturity) * _xlfn.NORM.S.DIST(bs_d1, FALSE)) / (spot_price * implied_volatlity * SQRT(time_to_maturity)) -> 0.00042358569 | D7: =C7*lot_size -> 0.021179284 | F7: Γ Gamma | G7: =0.5 * $D$7 * ($C$15^2) -> 105.89642 | H7: =G7/$G$10 -> 0.021574496 | J7: Γ Gamma | K7: =0.5 * $D$7 * ($C$15^2) -> 105.89642 | L7: =ABS(K7)/(ABS($K$6)+ABS($K$7)+ABS($K$8)+ABS($K$9)) -> 0.020956598
B8: V Vega (per 1% vol) | C8: =(spot_price * EXP(-dividend_yield * time_to_maturity) * SQRT(time_to_maturity) * _xlfn.NORM.S.DIST(bs_d1, FALSE)) / 100 -> 24.601857 | D8: =C8*lot_size -> 1230.0928 | F8: V Vega (per 1% vol) | G8: =$D$8 * $C$16 -> 2460.1857 | H8: =G8/$G$10 -> 0.50121868 | J8: V Vega (per 1% vol) | K8: =$D$8 * $C$16 -> 2460.1857 | L8: =ABS(K8)/(ABS($K$6)+ABS($K$7)+ABS($K$8)+ABS($K$9)) -> 0.48686367
B9: Θ Call Theta (Daily) | C9: =(-EXP(-dividend_yield * time_to_maturity) * (spot_price * _xlfn.NORM.S.DIST(bs_d1, FALSE) * implied_volatlity) / (2 * SQRT(time_to_maturity)) - risk_free_rate * strike_price * EXP(-risk_free_rate * time_to_maturity) * n_d2 + dividend_yield * spot_price * EXP(-dividend_yield * time_to_maturity) * n_d1) / 365 -> -8.0583044 | D9: =C9*lot_size -> -402.91522 | F9: Θ Call Theta (Daily) | G9: =D9 * $C$17 -> -402.91522 | H9: =G9/$G$10 -> -0.082086746 | J9: Θ Put Theta (Daily) | K9: =D10 * $C$17 -> -238.28565 | L9: =ABS(K9)/(ABS($K$6)+ABS($K$7)+ABS($K$8)+ABS($K$9)) -> 0.047156045
B10: Θ Put Theta (Daily) | C10: =(-EXP(-dividend_yield * time_to_maturity) * (spot_price * _xlfn.NORM.S.DIST(bs_d1, FALSE) * implied_volatlity) / (2 * SQRT(time_to_maturity)) + risk_free_rate * strike_price * EXP(-risk_free_rate * time_to_maturity) * _xlfn.NORM.S.DIST(-bs_d2, TRUE) - dividend_yield * spot_price * EXP(-dividend_yield * time_to_maturity) * _xlfn.NORM.S.DIST(-bs_d1, TRUE)) / 365 -> -4.765713 | D10: =C10*lot_size -> -238.28565 | F10: Total Call PnLAttribution | G10: =SUM(G7:G9,G6) -> 4908.4077 | H10: =SUM(H6:H9) -> 1 | J10: Total Put PnLAttribution | K10: =SUM(K7:K9,K6) -> 79.03371 | L10: =SUM(L6:L9) -> 1
B11: ρ Call Rho (per 1%) | C11: =(strike_price * time_to_maturity * EXP(-risk_free_rate * time_to_maturity) * n_d2) / 100 -> 9.3262051 | D11: =C11*lot_size -> 466.31025
B12: ρ Put Rho (per 1%) | C12: =(-strike_price * time_to_maturity * EXP(-risk_free_rate * time_to_maturity) * _xlfn.NORM.S.DIST(-bs_d2, TRUE)) / 100 -> -8.1755104 | D12: =C12*lot_size -> -408.77552
B14: PnL Scenario Simulator
B15: Nifty Change (Points) | C15: 100
B16: VIX Change (%) | C16: 2
B17: Days Passed | C17: 1

Sheet 05_Sensitivity_Matrix
B2: 📊 Call Premium Sensitivity Matrix — Total Value Per Lot (₹) | Red=Low · Yellow=Mid · Green=High
B3: ↖ Live Value (₹)
B4: ='03_BS_Engine'!D11 -> 21065.176 | C4: 0.1 | D4: 0.12 | E4: 0.14 | F4: 0.15 | G4: 0.16 | H4: 0.18 | I4: 0.2 | J4: 0.22 | K4: 0.24 | L4: 0.26
B5: 20000 | C5: 5.1955011 | D5: 40.340293 | E5: 153.38928 | F5: 254.64477 | G5: 392.12844 | H5: 787.37129 | I5: 1351.0797 | J5: 2081.5015 | K5: 2968.9208 | L5: 3999.8894
B6: 20400 | C6: 57.284641 | D6: 234.93541 | E6: 603.08503 | F6: 868.00577 | G6: 1187.5562 | H6: 1984.7067 | I6: 2976.0643 | J6: 4138.133 | K6: 5447.4284 | L6: 6882.6151
B7: 20800 | C7: 401.46863 | D7: 1006.0284 | E7: 1899.6702 | F7: 2442.8905 | G7: 3042.7628 | H7: 4390.5494 | I7: 5903.3711 | J7: 7548.8869 | K7: 9301.5336 | L7: 11141.298
B8: 21200 | C8: 1874.8484 | D8: 3271.3602 | E8: 4905.9593 | F8: 5790.1718 | G8: 6710.0842 | H8: 8637.0275 | I8: 10654.905 | J8: 12741.575 | K8: 14881.329 | L8: 17062.778 | O8: 0.15
B9: 21600 | C9: 6141.7085 | D9: 8356.7201 | E9: 10636.613 | F9: 11793.115 | G9: 12957.983 | H9: 15307.368 | I9: 17676.503 | J9: 20060.041 | K9: 22454.371 | L9: 24856.97 | O9: 22000
B10: 22000 | C10: 14930.808 | D10: 17379.7 | E10: 19835.538 | F10: 21065.176 | G10: 22295.664 | H10: 24758.587 | I10: 27223.403 | J10: 29689.528 | K10: 32156.567 | L10: 34624.239 | O10: 0.08
B11: 22400 | C11: 28609.581 | D11: 30531.534 | E11: 32602.143 | F11: 33676.722 | G11: 34771.543 | H11: 37009.398 | I11: 39296.411 | J11: 41619.794 | K11: 43970.773 | L11: 46343.137
B12: 22800 | C12: 45886.903 | D12: 46980.197 | E12: 48365.874 | F12: 49145.857 | G12: 49973.894 | H12: 51749.986 | I12: 53654.185 | J12: 55657.332 | K12: 57738.025 | L12: 59880.361
B13: 23200 | C13: 64998.78 | D13: 65459.909 | E13: 66206.502 | F13: 66681.457 | G13: 67218.448 | H13: 68458.988 | I13: 69890.089 | J13: 71478.109 | K13: 73195.077 | L13: 75018.322
B14: 23600 | C14: 84769.304 | D14: 84916.994 | E14: 85245.55 | F14: 85490.493 | G14: 85791.562 | H14: 86559.658 | I14: 87535.963 | J14: 88698.784 | K14: 90024.734 | L14: 91491.67
B16: Put Premium Matrix (Downside Risk)
B18: ='03_BS_Engine'!D12 -> 16241.6 | C18: 0.1 | D18: 0.12 | E18: 0.14 | F18: 0.15 | G18: 0.16 | H18: 0.18 | I18: 0.2 | J18: 0.22 | K18: 0.24 | L18: 0.26
B19: 20000 | C19: 95061.692 | D19: 95096.836 | E19: 95209.885 | F19: 95311.141 | G19: 95448.625 | H19: 95843.867 | I19: 96407.576 | J19: 97137.998 | K19: 98025.417 | L19: 99056.386
B20: 20400 | C20: 75137.766 | D20: 75315.417 | E20: 75683.567 | F20: 75948.488 | G20: 76268.038 | H20: 77065.188 | I20: 78056.546 | J20: 79218.615 | K20: 80527.91 | L20: 81963.097
B21: 20800 | C21: 55505.936 | D21: 56110.496 | E21: 57004.138 | F21: 57547.358 | G21: 58147.23 | H21: 59495.017 | I21: 61007.838 | J21: 62653.354 | K21: 64406.001 | L21: 66245.765
B22: 21200 | C22: 37003.301 | D22: 38399.813 | E22: 40034.412 | F22: 40918.625 | G22: 41838.537 | H22: 43765.481 | I22: 45783.358 | J22: 47870.028 | K22: 50009.781 | L22: 52191.231
B23: 21600 | C23: 21294.147 | D23: 23509.159 | E23: 25789.052 | F23: 26945.554 | G23: 28110.422 | H23: 30459.807 | I23: 32828.941 | J23: 35212.479 | K23: 37606.81 | L23: 40009.409
B24: 22000 | C24: 10107.232 | D24: 12556.124 | E24: 15011.962 | F24: 16241.6 | G24: 17472.088 | H24: 19935.011 | I24: 22399.827 | J24: 24865.953 | K24: 27332.991 | L24: 29800.663
B25: 22400 | C25: 3809.9912 | D25: 5731.9442 | E25: 7802.5529 | F25: 8877.1318 | G25: 9971.9525 | H25: 12209.808 | I25: 14496.82 | J25: 16820.204 | K25: 19171.183 | L25: 21543.546
B26: 22800 | C26: 1111.2986 | D26: 2204.592 | E26: 3590.2693 | F26: 4370.2523 | G26: 5198.2894 | H26: 6974.3817 | I26: 8878.5802 | J26: 10881.728 | K26: 12962.421 | L26: 15104.757
B27: 23200 | C27: 247.16092 | D27: 708.28997 | E27: 1454.8831 | F27: 1929.8384 | G27: 2466.8286 | H27: 3707.3685 | I27: 5138.4697 | J27: 6726.4903 | K27: 8443.4575 | L27: 10266.703
B28: 23600 | C28: 41.670922 | D28: 189.36054 | E28: 517.91673 | F28: 762.85974 | G28: 1063.9289 | H28: 1832.0249 | I28: 2808.3301 | J28: 3971.151 | K28: 5297.1008 | L28: 6764.0368
B30: Delta Matrix (Spot vs Time to Maturity) | I30: Agar NIFTY ₹1 move kare, to poore lot ka premium approx ₹27.45 move karega.
B32: ='04_Risk_Greeks'!D5 -> 27.452409 | C32: 0.08 | D32: 0.06 | E32: 0.04 | F32: 0.02 | G32: 0.01 | H32: 0.002
B33: 20000 | C33: 0.84585138 | D33: 0.3228347 | E33: 0.050233058 | F33: 0.00023496241 | G33: 6.9818148e-09 | H33: 2.7080983e-44
B34: 20400 | C34: 2.4461497 | D34: 1.2876002 | E34: 0.3787194 | F34: 0.011759559 | G34: 1.5118351e-05 | H34: 6.7657422e-28
B35: 20800 | C35: 5.7745687 | D35: 3.8985143 | E35: 1.8704003 | F35: 0.24576953 | G35: 0.0054935097 | H35: 1.832678e-15
B36: 21200 | C36: 11.345635 | D36: 9.1953929 | E36: 6.2872196 | F36: 2.3053907 | G36: 0.38238732 | H36: 9.3855375e-07
B37: 21600 | C37: 18.937478 | D37: 17.375322 | E37: 15.010048 | F37: 10.553058 | G37: 5.9579732 | H37: 0.16539643
B38: 22000 | C38: 27.452409 | D38: 27.129365 | E38: 26.743655 | F38: 26.237237 | G38: 25.876829 | H38: 25.393207
B39: 22400 | C39: 35.393044 | D39: 36.231176 | E39: 37.706004 | F39: 40.941676 | G39: 44.668684 | H39: 49.828151
B40: 22800 | C40: 41.609007 | D40: 42.961201 | E40: 44.950033 | F40: 47.966323 | G40: 49.61024 | H40: 49.998498
B41: 23200 | C41: 45.730219 | D41: 46.95104 | E41: 48.394074 | F41: 49.727943 | G41: 49.984069 | H41: 49.9985
B42: 23600 | C42: 48.063967 | D42: 48.868568 | E42: 49.591175 | F42: 49.966346 | G42: 49.992443 | H42: 49.9985
B43: 24000 | C43: 49.201667 | D43: 49.623472 | E43: 49.900012 | F43: 49.984221 | G43: 49.9925 | H43: 49.9985
B45: Gamma Matrix
B47: ='04_Risk_Greeks'!D7 -> 0.021179284 | C47: 0.08 | D47: 0.06 | E47: 0.04 | F47: 0.02 | G47: 0.01 | H47: 0.002
...

Sheet 06_Advanced_Applications
B2: 🏦 Portfolio Hedging & Risk Metrics | Indian Equity Portfolio Delta-Hedge
B4: SECTION A · Portfolio Parameters (Blue = User Inputs)
B5: Parameter | C5: Value | D5: Description
B6: Portfolio Value (₹) | C6: 10000000 | D6: ₹1,00,00,000 = ₹1 Crore Indian equity portfolio
B7: Portfolio Beta (β) | C7: 1.2 | D7: Systematic risk vs NIFTY 50 (1.2 = 20% more volatile than index)
B9: SECTION B · Delta-Hedge Calculation | NIFTY 50 Put Options
B10: Metric | C10: Value | D10: Source / Formula
B11: Put Delta (per share) | C11: ='04_Risk_Greeks'!C6 -> -0.44975255 | D11: Linked from Greeks sheet
B12: NIFTY Spot Price (₹) | C12: ='02_Market_Data'!C6 -> 22000 | D12: Linked from Market Data
B13: Lot Size | C13: ='02_Market_Data'!C12 -> 50 | D13: Linked from Market Data
B14: Beta-Adj Portfolio Value (₹) | C14: ='06_Advanced_Applications'!C6*'06_Advanced_Applications'!C7 -> 12000000 | D14: Portfolio Value × Beta
B15: ✅ NIFTY Puts Required (Lots) | C15: =ROUNDUP(('06_Advanced_Applications'!C6*'06_Advanced_Applications'!C7)/('02_Market_Data'!C6*ABS('04_Risk_Greeks'!C6)*'02_Market_Data'!C12),0) -> 25 | D15: ROUNDUP((PV×β)/(S×|Δp|×N),0)
B16: Total Hedge Cost (₹) | C16: =C15*'03_BS_Engine'!C12*'02_Market_Data'!C12 -> 406040.01 | D16: Lots × Put Premium × Lot Size
B17: Hedge Cost as % of Portfolio | C17: =C16/'06_Advanced_Applications'!C6 -> 0.040604001 | D17: Cost/Portfolio Value
B19: SECTION C · Portfolio Risk Metrics | Parametric VaR
B20: Risk Metric | C20: Value | D20: Method
B21: 1-Day 99% VaR (Parametric, ₹) | C21: ='06_Advanced_Applications'!C6*'06_Advanced_Applications'!C7*'02_Market_Data'!C10*SQRT(1/252)*2.326 -> 263743.61 | D21: V×β×σ×√(1/252)×2.326
B22: 10-Day 99% VaR (Basel Scale, ₹) | C22: =C21*SQRT(10) -> 834030.52 | D22: 1-Day VaR × √10
B23: Annualised Portfolio Volatility | C23: ='06_Advanced_Applications'!C7*'02_Market_Data'!C10 -> 0.18 | D23: β × NIFTY σ
B24: Daily Break-Even Move (₹) | C24: ='02_Market_Data'!C6*'02_Market_Data'!C10*SQRT(1/252) -> 207.88046 | D24: S×σ×√(1/252)
